# 10. Exception

## 1. Exceptions

### exception

- 심각 X 에러, 비정상적인 상황으로 예외 발생시 기존 실행이 지속되도록 처리되어야함(처리안되면 종료됨)
- 적절한 예외 처리가 중요(Java, ML, C++, Python….)
- 예외처리를 위해 필요한 3가지는? → `예외 정의`, `예외 발생`, `예외 처리`

```
try {
	raise E; (1)   // 예외 발생
	(2)
}catch(E){
	(3)            // 예외 처리
}
	(4)
```

### ❗️Resumption Model(재개모델) VS Termination Model(종료 모델)

재개모델은 예외발생시 예외처리후 예외를 발생시킨 코드로 재개하여 계속 실행한다.(위의 `1→3→2` 순)

종료모델은 예외를 발생시킨 코드로 재개하지않고 try문을 끝내고 다음 문장을 실행(`1→3→4`)

`exc id;` `raise id;` `try <stmt> catch(id) <stmt>`

### ❗️암기 필수

```
<command> -> exc id //에러 정의
<stmt> -> raise id; //에러 발생
				  | try <stmt> catch(id) <stmt> //에러 처리
```

### 코드에 적용

```
exc InvalidInput; //에러 정의
let
	int x = 0; int y = 1;
in
	read x;
	if(x < 0) then
		  raise InvalidInput //에러 발생
	else 
		while(x != 0) {
			y = y * x;
			x = x - 1;
	}
	print y;
end
```

### ❗️try <stmt> catch(id) <stmt>로 바꿔보시오

```
exc InvalidInput; //에러 정의
let
	int x = 0; int y = 1;
in
	read x;
	try{
		if(x < 0) then
		  raise InvalidInput //에러 발생
		else 
			while(x != 0) {
				y = y * x;
				x = x - 1;
		}
		print y;
	} catch(InvalidInput) print "invalid input";
end
```

### Multiple catch Clauses

예외 타입에 따라 다르게 처리된다

```
try
	S1
catch(E1) S2
catch(E2) S3

이렇게하거나

try
	try
			S1
	catch(E1) S2
	
```

## 2. Python Exception

`try:`

실행코드

`except:`

예외처리코드

```
⭐️(아래에서도 계속 쓰일 예제)

try:
	x = int(input('Enter the number to divide: '))
	y = 10 / x
	print(y)
except: 
	print("예외발생!")
---------------------------------------------------------------
Enter the number to divide: 0
예외발생!
```

### 특정 예외 처리

`try:`

실행코드

`except 예외이름1:`

예외처리코드

`except 예외이름2:`

예외처리코드

`else: 예외X시 실행할 코드`

`finally: 예외발생여부 관계없이 실행할 코드`

### **Specific Exception Handling**

```
⭐️(아래에서도 계속 쓰일 예제)

try:
	x = int(input('Enter the number to divide: '))
	y = 10 / x
	print(y)
except ZeroDivisionError: 
	print('Cannot divide by zero.')
---------------------------------------------------------------
⚫ 실행결과
Enter the number to divide: 0
Cannot divide by zero.
⚫ 실행결과 //에러가 안걸렸을때❗️
Enter the number to divide : 10.0
Traceback (most recent call last):
File "<pyshell#15>", line 2, in <module>
x = int(input('Enter the number to divide: '))
ValueError: invalid literal for int() with base 10: '10.0'
```

### **Multiple except Clauses**

```
try:
	x = int(input('Enter the number to divide: '))
	print(10 / x)
except ZeroDivisionError: # Triggered when dividing by zero
	print('Cannot divide by zero.')
except ValueError: # Passing an inappropriate value to the int function
	print('The entered value is not an integer.’)

---------------------------------------------------------------
⚫ 실행결과
Enter the number to divide: 10.0
The entered value is not an integer.
```

### **Nested try Statement**

```
try:
	try:
			x = int(input('Enter the number to divide: '))
			print(10 / x)
	except ZeroDivisionError: # Triggered when dividing by zero
			print('Cannot divide by zero.')
except ValueError: # Passing an inappropriate value to the int function
	print('The entered value is not an integer.')
```

### **try-except-as⭐️**

```
예외 에러메시지 받아내고 싶을때
try:
		x = int(input('Enter the number to divide: '))
		print(10 / x)
except ZeroDivisionError as e:
		print('Cannot divide by zero: ', e)
except ValueError as e:
		print('The entered value is not an integer: ', e)

---------------------------------------------------------------
⚫ 실행결과
Enter the number to divide: 0
Cannot divide by zero: division by zero
⚫ Execution result
Enter the number to divide: 10.0
The entered value is not an integer: invalid literal for int() with base 10: '10.0'
```

### **try-finally Example**

```
y = [10, 20, 30]
try:
	index = int(input(‘Enter the index: ')) //인덱스 입력
	x = int(input('Enter the number to divide: ')) //분모 입력
	print(y[index] / x) 
except ZeroDivisionError as e: //0나누기 에러
	print('Cannot divide by zero: ', e)
except IndexError as e: //인덱스 에러
	print('Invalid index: ', e)
except ValueError as e: // 정수아닐때 에러
	print('The entered value is not an integer : ', e)
finally: //⭐️무조건 실행
	print(‘The end of the try statement.')
```

### **Exception Propagation⭐️**

호출된 함수 내에서 발생된 예외는 그 함수 내에서 처리되지 않으면

호출의 역순으로 처리될 때까지 호출자 함수에게 전파되는데, 이를 예외전파(**Exception Propagation)**라고함.

### 예제

```
def C(x):
	return 8 / x # Error occurs when x is 0.
def B(y):
	return C(y - 1) # Error occurs when y is 1.
def A( ):
	print(B(int(input())))

A( )

---------------------------------------------------------------
⚫ 실행결과
1
Traceback (most recent call last):
File "<pyshell#6>", line 1, in <module>
A() // 
File "<pyshell#5>", line 2, in c
print(B(int(input()))) //
File "<pyshell#3>", line 2, in b
return C(y - 1) // 
File "<pyshell#1>", line 2, in a
return 8 / x //
ZeroDivisionError: division by zero
```

### 예제

```
def C(x):
	return 8 / x # Error occurs when x is 0
def B(y):
	return C(y - 1) # Error occurs when y is 1
def A( ):
	try:
		print(B(int(input())))
	except ZeroDivisionError:
		print('Cannot divide by zero.')
A( )

---------------------------------------------------------------
⚫ 실행결과
1
Cannot divide by zero. //바로캐치
```

### Python 예외 계층 구조

![%E1%84%89%E1%85%B3%E1%84%8F%E1%85%B3%E1%84%85%E1%85%B5%E1%86%AB%E1%84%89%E1%85%A3%E1%86%BA%202023-12-14%20%E1%84%8B%E1%85%A9%E1%84%8C%E1%85%A5%E1%86%AB%204 33 27](https://github.com/puretension/UnivStudyRepo/assets/106448279/c672e580-de0d-4392-a23c-9c27212a2887)

### 포괄적 예외 처리

```
try:
except ZeroDivisionError:

try:
except IndexError:

try:
except Exception: 
// 대부분의 일반적인 프로그램 오류를 잡기 위해 사용

try:
except BaseException:
// 모든 종류의 예외를 잡기 위해 사용(계층구조 참고)

// It is difficult to handle specific exceptions appropriately.
```

### 에러 발생 → `raise ExceptionName or raise ExceptionName(message)`

raise키워드 이용해서 발생

```
>>> raise ZeroDivisionError('Cannot divide by zero') //고의로 발생시키기
Traceback (most recent call last):
File "<stdin>", line 1, in <module>
ZeroDivisionError: Cannot divide by zero
```

### 에러 정의

이미 내장된 예외이름도 가능하나, 사용자가 정의한 예외이름도 가능함

사용자 정의 예외 클래스인 `NegativeInputException`을 정의하는 방법

`input_total` 함수는 사용자로부터 입력을 받아 합계를 계산.

입력값이 음수일 경우 `NegativeInputException`을 발생시키며, 예외가 발생하면 해당 예외의 메시지를 출력하고 합계를 반환

```
class NegativeInputException(Exception):
	pass

def input_total():
		try:
				total = 0
				while = True:
					score = int(input())
					if score < 0: raise NegativeInputException
				total = total + score
		except NegativeInputException as e:
				 print(e)
				 return total

---------------------------------------------------------------
⚫ 실행결과
input_total() 입력시,
10
20
30
-1
(공백) -> 에러메시지가 출력안된다. 아래참고
60
```

### 에러메시지 생성하는 방법❗️(에러메시지 안나오는거주고, 2가지 방법으로 생성해보라)

- `raise NegativeInputException(”음수 입력입니다”)`

  → **예외 메시지와 함께 예외 발생시키기**

- `def __str__ (self): return “음수입력입니다”`

  → NegativeInputException클래스 내부(pass부분)에 `__str__` 메소드 구현


## 3. **Java Exception**

- Java에서는 예외타입을 클래스로 선언하고 사용
- Exception객체는 1급(first-class) 객체

![%E1%84%89%E1%85%B3%E1%84%8F%E1%85%B3%E1%84%85%E1%85%B5%E1%86%AB%E1%84%89%E1%85%A3%E1%86%BA%202023-12-14%20%E1%84%8B%E1%85%A9%E1%84%92%E1%85%AE%206 05 58](https://github.com/puretension/UnivStudyRepo/assets/106448279/41479c41-eb95-46aa-8cc5-16bb5aa608ae)

### Exception클래스를 상속받는 에러 종류

| ArithmeticException | 0나누기때 발생하며, RuntimeException을 직상속 |
| --- | --- |
| ArrayIndexOutofBoundException | index > arraysize |
| NegativeArraySizeException | arraysize가 음수 |
|  NullPointerException | 생성되지않은 객체를 이용해서 객체멤버 접근시 발생 |

### 커스텀 예외클래스 구현하기

```java
public class NegativeInputException extends Exception{ // Exception 상속 필수
		private String reason = "Negative input";
		NegativeInputException() { //생성자
			System.out.println(reason + "is received")
	}
}
```

### 예외 발생 및 처리

`throw 예외객체` → throws랑 다르다

발생한 예외를 처리X ? → `call stack trace`를 포함하는 에러메시지 출력(main ~ 예외발생까지 과정show)

### try-catch(E1 e)-catch(E2 e)-finally

```java
class Grade {
	int newGrade, total;
	void totalGrade( ) {
		Scanner scan = new Scanner (System.in);
		try {
			while (true) {
				System.out.println("Please input a grade");
				newGrade = scan.nextInt( );
				if (newGrade < 0)
					throw new NegativeInputException( );
				if (newGrade <= 100)
					total = total + newGrade;
				else System.out.println("Out of range input !");
			}
		} catch(NegativeInputException x) {
				System.out.println(x);
				System.out.println("Total:" + total);
			}
	}
}

public static void main(String[] args) {
	Grade grade = new Grade();
	grade.totalGrade();
}

---------------------------------------------------------------
⚫ 실행결과
Please input a grade
85
Please input a grade
90
Please input a grade
75
Please input a grade
800
Out of range input !
Please input a grade
80
Please input a grade
-1
Negative input is received
NegativeInputException
Total: 330
```

### 예외 전파

## 4. Exception Checking(Java)

### ****Exception Checking in the Compiler****

예외가 발생할만한 코드가 있다면 `try-catch`문은 필수임(없다면 바로 종료)

Java는 발생할 예외를 처리할만한 try-catch가 없다면, **컴파일러**가 이를 미리검사하는

`exception checking(예외검사)` 를 수행하여, 에러가 있을곳에 try-catch가 없다면 컴파일 오류 메시지 출력

→ try-catch가 꼭 해결책은 아니다. `throws`를 메서드 헤더에 선언해도된다

```java
public class Propagate
{
	void input() throws NegativeInputException {
		int age;
		Scanner scan = new Scanner(System.in);
		System.out.println("input 메소드 시작");
		age = scan.nextInt( );
		if (age < 0)
		throw new NegativeInputException( );
		System.out.println("input 메소드 끝");
	}
	void via() throws NegativeInputException {
		System.out.println("via 메소드 시작");
		input();
		System.out.println("via 메소드 끝");
}

public static void main(String[] args) {
	Propagate p = new Propagate();
	System.out.println("main 메소드 시작");
	try {
				p.via();
	} catch (NegativeInputException m) {
				System.out.println(m);
	}
				System.out.println("main 메소드 끝");
	}
}
```

### ****Checked Exception vs Unchecked Exception****

Java Compiler의 예외 검사 과정

- 메서드내에 발생할만한 예외가 있을때 try-catch있는지 OR 메서드 헤더에 throws있는지
- 메서드 A에서 메서드 B호출시 호출되는 메서드 헤더(callee method header)에 throws로 선언된 예외정보 확인후, try-catch있는지 확인하고, 없다면 호출되는 메서드 헤더에 이 예외가 선언되었는지 확인

### ❗️Checked Exception(검사예외) VS Unchecked Exception(비검사 예외)

### Checked Exception(검사 예외)

- **예외 발생시, 컴파일러가 미리 처리가능한지 확인**
- RuntimeException제외한 모든 에러가 속함
- 메서드내에서 처리X에러는 throws선언으로 해결

### Unchecked Exception(비검사 예외)

- RuntimeException상속하는 모든 에러가 속함
- 컴파일러는 예외를 처리해야 하는지 사전에 검사X(unchecked)
- 프로그래머가 **직접** 예외처리해줘야함